<?xml version="1.0" encoding="utf-8"?>
<!-- This URDF was automatically created by SolidWorks to URDF Exporter! Originally created by Stephen Brawner (brawner@gmail.com) 
     Commit Version: 1.5.1-0-g916b5db  Build Version: 1.5.7152.31018
     For more information, please see http://wiki.ros.org/sw_urdf_exporter -->
<robot
  name="prototype_urdf">
  <link
    name="base_link">
    <inertial>
      <origin
        xyz="-4.5523E-05 0.14559 -0.13975"
        rpy="0 0 0" />
      <mass
        value="5.4656" />
      <inertia
        ixx="0.012713"
        ixy="3.0137E-07"
        ixz="-0.00011104"
        iyy="0.073389"
        iyz="-1.185E-06"
        izz="0.068413" />
    </inertial>
    <visual>
      <origin
        xyz="0 0 0"
        rpy="0 0 0" />
      <geometry>
        <mesh
          filename="package://prototype_urdf/meshes/base_link.STL" />
      </geometry>
      <material
        name="">
        <color
          rgba="0.75294 0.75294 0.75294 1" />
      </material>
    </visual>
    <collision>
      <origin
        xyz="0 0 0"
        rpy="0 0 0" />
      <geometry>
        <mesh
          filename="package://prototype_urdf/meshes/base_link.STL" />
      </geometry>
    </collision>
  </link>
  <link
    name="suspension_front_left">
    <inertial>
      <origin
        xyz="-0.022238 0.0053253 0.057836"
        rpy="0 0 0" />
      <mass
        value="0.092965" />
      <inertia
        ixx="7.8332E-06"
        ixy="2.4021E-09"
        ixz="2.0772E-08"
        iyy="1.8337E-05"
        iyz="-7.1449E-07"
        izz="1.2259E-05" />
    </inertial>
    <visual>
      <origin
        xyz="0 0 0"
        rpy="0 0 0" />
      <geometry>
        <mesh
          filename="package://prototype_urdf/meshes/suspension_front_left.STL" />
      </geometry>
      <material
        name="">
        <color
          rgba="0.75294 0.75294 0.75294 1" />
      </material>
    </visual>
    <collision>
      <origin
        xyz="0 0 0"
        rpy="0 0 0" />
      <geometry>
        <mesh
          filename="package://prototype_urdf/meshes/suspension_front_left.STL" />
      </geometry>
    </collision>
  </link>
  <joint
    name="suspension_front_left"
    type="prismatic">
    <origin
      xyz="-0.16517 0.20237 0.13322"
      rpy="1.6863 -1.1874 -0.0018512" />
    <parent
      link="base_link" />
    <child
      link="suspension_front_left" />
    <axis
      xyz="0 0 0" />
    <limit
      lower="-0.04"
      upper="0"
      effort="1000"
      velocity="1000" />
    <dynamics
      damping="0"
      friction="0" />
  </joint>
  <link
    name="wheel_front_left">
    <inertial>
      <origin
        xyz="1.4086E-06 -0.087061 -3.1501E-05"
        rpy="0 0 0" />
      <mass
        value="0.0005833" />
      <inertia
        ixx="8.6958E-07"
        ixy="1.2157E-11"
        ixz="-1.9549E-11"
        iyy="1.6137E-06"
        iyz="-2.7388E-10"
        izz="8.6989E-07" />
    </inertial>
    <visual>
      <origin
        xyz="0 0 0"
        rpy="0 0 0" />
      <geometry>
        <mesh
          filename="package://prototype_urdf/meshes/wheel_front_left.STL" />
      </geometry>
      <material
        name="">
        <color
          rgba="1 0 0 1" />
      </material>
    </visual>
    <collision>
      <origin
        xyz="0 0 0"
        rpy="0 0 0" />
      <geometry>
        <mesh
          filename="package://prototype_urdf/meshes/wheel_front_left.STL" />
      </geometry>
    </collision>
  </link>
  <joint
    name="wheel_front_left"
    type="continuous">
    <origin
      xyz="-0.053094 -0.014583 0.060145"
      rpy="2.8335 1.2107 0.096305" />
    <parent
      link="suspension_front_left" />
    <child
      link="wheel_front_left" />
    <axis
      xyz="0 1 0" />
    <limit
      effort="3.1"
      velocity="7" />
  </joint>
  <link
    name="suspension_front_right">
    <inertial>
      <origin
        xyz="-0.022238 0.0053253 0.057836"
        rpy="0 0 0" />
      <mass
        value="0.092965" />
      <inertia
        ixx="7.8332E-06"
        ixy="2.402E-09"
        ixz="2.0772E-08"
        iyy="1.8337E-05"
        iyz="-7.1449E-07"
        izz="1.2259E-05" />
    </inertial>
    <visual>
      <origin
        xyz="0 0 0"
        rpy="0 0 0" />
      <geometry>
        <mesh
          filename="package://prototype_urdf/meshes/suspension_front_right.STL" />
      </geometry>
      <material
        name="">
        <color
          rgba="0.75294 0.75294 0.75294 1" />
      </material>
    </visual>
    <collision>
      <origin
        xyz="0 0 0"
        rpy="0 0 0" />
      <geometry>
        <mesh
          filename="package://prototype_urdf/meshes/suspension_front_right.STL" />
      </geometry>
    </collision>
  </link>
  <joint
    name="suspension_front_right"
    type="prismatic">
    <origin
      xyz="0.16284 0.20176 0.1322"
      rpy="-1.4553 -1.1874 3.1397" />
    <parent
      link="base_link" />
    <child
      link="suspension_front_right" />
    <axis
      xyz="0 0 0" />
    <limit
      lower="-0.04"
      upper="0"
      effort="1000"
      velocity="1000" />
    <dynamics
      damping="0"
      friction="0" />
  </joint>
  <link
    name="wheel_front_right">
    <inertial>
      <origin
        xyz="1.4086E-06 -0.089608 -3.1501E-05"
        rpy="0 0 0" />
      <mass
        value="0.0005833" />
      <inertia
        ixx="8.6958E-07"
        ixy="1.2157E-11"
        ixz="-1.9549E-11"
        iyy="1.6137E-06"
        iyz="-2.7388E-10"
        izz="8.6989E-07" />
    </inertial>
    <visual>
      <origin
        xyz="0 0 0"
        rpy="0 0 0" />
      <geometry>
        <mesh
          filename="package://prototype_urdf/meshes/wheel_front_right.STL" />
      </geometry>
      <material
        name="">
        <color
          rgba="1 0 0 1" />
      </material>
    </visual>
    <collision>
      <origin
        xyz="0 0 0"
        rpy="0 0 0" />
      <geometry>
        <mesh
          filename="package://prototype_urdf/meshes/wheel_front_right.STL" />
      </geometry>
    </collision>
  </link>
  <joint
    name="wheel_front_right"
    type="continuous">
    <origin
      xyz="-0.052142 0.02758 0.055255"
      rpy="-2.888 -1.1309 2.5256" />
    <parent
      link="suspension_front_right" />
    <child
      link="wheel_front_right" />
    <axis
      xyz="0 1 0" />
    <limit
      effort="3.1"
      velocity="7" />
  </joint>
  <link
    name="suspension_back_left">
    <inertial>
      <origin
        xyz="-0.022237 0.0053253 0.057836"
        rpy="0 0 0" />
      <mass
        value="0.092965" />
      <inertia
        ixx="7.8332E-06"
        ixy="2.4021E-09"
        ixz="2.0772E-08"
        iyy="1.8337E-05"
        iyz="-7.1449E-07"
        izz="1.2259E-05" />
    </inertial>
    <visual>
      <origin
        xyz="0 0 0"
        rpy="0 0 0" />
      <geometry>
        <mesh
          filename="package://prototype_urdf/meshes/suspension_back_left.STL" />
      </geometry>
      <material
        name="">
        <color
          rgba="0.75294 0.75294 0.75294 1" />
      </material>
    </visual>
    <collision>
      <origin
        xyz="0 0 0"
        rpy="0 0 0" />
      <geometry>
        <mesh
          filename="package://prototype_urdf/meshes/suspension_back_left.STL" />
      </geometry>
    </collision>
  </link>
  <joint
    name="suspension_back_left"
    type="prismatic">
    <origin
      xyz="-0.16528 -0.076934 0.13322"
      rpy="1.6863 -1.1874 0" />
    <parent
      link="base_link" />
    <child
      link="suspension_back_left" />
    <axis
      xyz="0 0 0" />
    <limit
      lower="-0.04"
      upper="0"
      effort="1000"
      velocity="1000" />
    <dynamics
      damping="0"
      friction="0" />
  </joint>
  <link
    name="wheel_back_left">
    <inertial>
      <origin
        xyz="1.4086E-06 -0.087061 -3.1501E-05"
        rpy="0 0 0" />
      <mass
        value="0.0005833" />
      <inertia
        ixx="8.6958E-07"
        ixy="1.2157E-11"
        ixz="-1.9549E-11"
        iyy="1.6137E-06"
        iyz="-2.7388E-10"
        izz="8.6989E-07" />
    </inertial>
    <visual>
      <origin
        xyz="0 0 0"
        rpy="0 0 0" />
      <geometry>
        <mesh
          filename="package://prototype_urdf/meshes/wheel_back_left.STL" />
      </geometry>
      <material
        name="">
        <color
          rgba="1 0 0 1" />
      </material>
    </visual>
    <collision>
      <origin
        xyz="0 0 0"
        rpy="0 0 0" />
      <geometry>
        <mesh
          filename="package://prototype_urdf/meshes/wheel_back_left.STL" />
      </geometry>
    </collision>
  </link>
  <joint
    name="wheel_back_left"
    type="continuous">
    <origin
      xyz="-0.053094 -0.014583 0.060145"
      rpy="0.10707 -0.017512 -2.7578" />
    <parent
      link="suspension_back_left" />
    <child
      link="wheel_back_left" />
    <axis
      xyz="0 1 0" />
    <limit
      effort="3.1"
      velocity="7" />
  </joint>
  <link
    name="suspension_back_right">
    <inertial>
      <origin
        xyz="-4.5523E-05 0.14559 -0.13975"
        rpy="0 0 0" />
      <mass
        value="5.4656" />
      <inertia
        ixx="0.012713"
        ixy="3.0137E-07"
        ixz="-0.00011104"
        iyy="0.073389"
        iyz="-1.185E-06"
        izz="0.068413" />
    </inertial>
    <visual>
      <origin
        xyz="0 0 0"
        rpy="0 0 0" />
      <geometry>
        <mesh
          filename="package://prototype_urdf/meshes/suspension_back_right.STL" />
      </geometry>
      <material
        name="">
        <color
          rgba="0.75294 0.75294 0.75294 1" />
      </material>
    </visual>
    <collision>
      <origin
        xyz="0 0 0"
        rpy="0 0 0" />
      <geometry>
        <mesh
          filename="package://prototype_urdf/meshes/suspension_back_right.STL" />
      </geometry>
    </collision>
  </link>
  <joint
    name="suspension_back_right"
    type="prismatic">
    <origin
      xyz="0.16273 -0.076934 0.1322"
      rpy="-1.4553 -1.1874 3.1416" />
    <parent
      link="base_link" />
    <child
      link="suspension_back_right" />
    <axis
      xyz="0 0 0" />
    <limit
      lower="-0.04"
      upper="0"
      effort="1000"
      velocity="1000" />
    <dynamics
      damping="0"
      friction="0" />
  </joint>
  <link
    name="wheel_back_right">
    <inertial>
      <origin
        xyz="1.4086E-06 -0.089579 -3.1501E-05"
        rpy="0 0 0" />
      <mass
        value="0.0005833" />
      <inertia
        ixx="8.6958E-07"
        ixy="1.2157E-11"
        ixz="-1.9549E-11"
        iyy="1.6137E-06"
        iyz="-2.7388E-10"
        izz="8.6989E-07" />
    </inertial>
    <visual>
      <origin
        xyz="0 0 0"
        rpy="0 0 0" />
      <geometry>
        <mesh
          filename="package://prototype_urdf/meshes/wheel_back_right.STL" />
      </geometry>
      <material
        name="">
        <color
          rgba="1 0 0 1" />
      </material>
    </visual>
    <collision>
      <origin
        xyz="0 0 0"
        rpy="0 0 0" />
      <geometry>
        <mesh
          filename="package://prototype_urdf/meshes/wheel_back_right.STL" />
      </geometry>
    </collision>
  </link>
  <joint
    name="wheel_back_right"
    type="continuous">
    <origin
      xyz="-0.052153 0.027553 0.055258"
      rpy="-0.10715 -0.043108 -0.38107" />
    <parent
      link="suspension_back_right" />
    <child
      link="wheel_back_right" />
    <axis
      xyz="0 1 0" />
    <limit
      effort="3.1"
      velocity="7" />
  </joint>
</robot>